{
 "cells": [
  {
   "cell_type": "code",
   "execution_count": 3,
   "metadata": {
    "collapsed": false
   },
   "outputs": [
    {
     "ename": "RuntimeError",
     "evalue": "module compiled against API version 0xa but this version of numpy is 0x9",
     "output_type": "error",
     "traceback": [
      "\u001b[0;31m---------------------------------------------------------------------------\u001b[0m",
      "\u001b[0;31mRuntimeError\u001b[0m                              Traceback (most recent call last)",
      "\u001b[0;31mRuntimeError\u001b[0m: module compiled against API version 0xa but this version of numpy is 0x9"
     ]
    },
    {
     "ename": "ImportError",
     "evalue": "Traceback (most recent call last):\n  File \"/Users/chaz/anaconda/lib/python2.7/site-packages/tensorflow/python/__init__.py\", line 61, in <module>\n    from tensorflow.python import pywrap_tensorflow\n  File \"/Users/chaz/anaconda/lib/python2.7/site-packages/tensorflow/python/pywrap_tensorflow.py\", line 28, in <module>\n    _pywrap_tensorflow = swig_import_helper()\n  File \"/Users/chaz/anaconda/lib/python2.7/site-packages/tensorflow/python/pywrap_tensorflow.py\", line 24, in swig_import_helper\n    _mod = imp.load_module('_pywrap_tensorflow', fp, pathname, description)\nImportError: numpy.core.multiarray failed to import\n\n\nFailed to load the native TensorFlow runtime.\n\nSee https://github.com/tensorflow/tensorflow/blob/master/tensorflow/g3doc/get_started/os_setup.md#import_error\n\nfor some common reasons and solutions.  Include the entire stack trace\nabove this error message when asking for help.",
     "output_type": "error",
     "traceback": [
      "\u001b[0;31m---------------------------------------------------------------------------\u001b[0m",
      "\u001b[0;31mImportError\u001b[0m                               Traceback (most recent call last)",
      "\u001b[0;32m<ipython-input-3-40bf8ae976e6>\u001b[0m in \u001b[0;36m<module>\u001b[0;34m()\u001b[0m\n\u001b[0;32m----> 1\u001b[0;31m \u001b[0;32mimport\u001b[0m \u001b[0mtensorflow\u001b[0m\u001b[0;34m\u001b[0m\u001b[0m\n\u001b[0m",
      "\u001b[0;32m/Users/chaz/anaconda/lib/python2.7/site-packages/tensorflow/__init__.py\u001b[0m in \u001b[0;36m<module>\u001b[0;34m()\u001b[0m\n\u001b[1;32m     22\u001b[0m \u001b[0;34m\u001b[0m\u001b[0m\n\u001b[1;32m     23\u001b[0m \u001b[0;31m# pylint: disable=wildcard-import\u001b[0m\u001b[0;34m\u001b[0m\u001b[0;34m\u001b[0m\u001b[0m\n\u001b[0;32m---> 24\u001b[0;31m \u001b[0;32mfrom\u001b[0m \u001b[0mtensorflow\u001b[0m\u001b[0;34m.\u001b[0m\u001b[0mpython\u001b[0m \u001b[0;32mimport\u001b[0m \u001b[0;34m*\u001b[0m\u001b[0;34m\u001b[0m\u001b[0m\n\u001b[0m\u001b[1;32m     25\u001b[0m \u001b[0;31m# pylint: enable=wildcard-import\u001b[0m\u001b[0;34m\u001b[0m\u001b[0;34m\u001b[0m\u001b[0m\n\u001b[1;32m     26\u001b[0m \u001b[0;34m\u001b[0m\u001b[0m\n",
      "\u001b[0;32m/Users/chaz/anaconda/lib/python2.7/site-packages/tensorflow/python/__init__.py\u001b[0m in \u001b[0;36m<module>\u001b[0;34m()\u001b[0m\n\u001b[1;32m     70\u001b[0m \u001b[0;32mfor\u001b[0m \u001b[0msome\u001b[0m \u001b[0mcommon\u001b[0m \u001b[0mreasons\u001b[0m \u001b[0;32mand\u001b[0m \u001b[0msolutions\u001b[0m\u001b[0;34m.\u001b[0m  \u001b[0mInclude\u001b[0m \u001b[0mthe\u001b[0m \u001b[0mentire\u001b[0m \u001b[0mstack\u001b[0m \u001b[0mtrace\u001b[0m\u001b[0;34m\u001b[0m\u001b[0m\n\u001b[1;32m     71\u001b[0m above this error message when asking for help.\"\"\" % traceback.format_exc()\n\u001b[0;32m---> 72\u001b[0;31m   \u001b[0;32mraise\u001b[0m \u001b[0mImportError\u001b[0m\u001b[0;34m(\u001b[0m\u001b[0mmsg\u001b[0m\u001b[0;34m)\u001b[0m\u001b[0;34m\u001b[0m\u001b[0m\n\u001b[0m\u001b[1;32m     73\u001b[0m \u001b[0;34m\u001b[0m\u001b[0m\n\u001b[1;32m     74\u001b[0m \u001b[0;31m# Protocol buffers\u001b[0m\u001b[0;34m\u001b[0m\u001b[0;34m\u001b[0m\u001b[0m\n",
      "\u001b[0;31mImportError\u001b[0m: Traceback (most recent call last):\n  File \"/Users/chaz/anaconda/lib/python2.7/site-packages/tensorflow/python/__init__.py\", line 61, in <module>\n    from tensorflow.python import pywrap_tensorflow\n  File \"/Users/chaz/anaconda/lib/python2.7/site-packages/tensorflow/python/pywrap_tensorflow.py\", line 28, in <module>\n    _pywrap_tensorflow = swig_import_helper()\n  File \"/Users/chaz/anaconda/lib/python2.7/site-packages/tensorflow/python/pywrap_tensorflow.py\", line 24, in swig_import_helper\n    _mod = imp.load_module('_pywrap_tensorflow', fp, pathname, description)\nImportError: numpy.core.multiarray failed to import\n\n\nFailed to load the native TensorFlow runtime.\n\nSee https://github.com/tensorflow/tensorflow/blob/master/tensorflow/g3doc/get_started/os_setup.md#import_error\n\nfor some common reasons and solutions.  Include the entire stack trace\nabove this error message when asking for help."
     ]
    }
   ],
   "source": [
    "import tensorflow "
   ]
  },
  {
   "cell_type": "code",
   "execution_count": null,
   "metadata": {
    "collapsed": true
   },
   "outputs": [],
   "source": []
  }
 ],
 "metadata": {
  "kernelspec": {
   "display_name": "Python [conda root]",
   "language": "python",
   "name": "conda-root-py"
  },
  "language_info": {
   "codemirror_mode": {
    "name": "ipython",
    "version": 2
   },
   "file_extension": ".py",
   "mimetype": "text/x-python",
   "name": "python",
   "nbconvert_exporter": "python",
   "pygments_lexer": "ipython2",
   "version": "2.7.12"
  }
 },
 "nbformat": 4,
 "nbformat_minor": 1
}
